Workbook

Sheet 00 | جلد و هویت
A1: ME | C1: MAJID EISAPOUR
C2: Design & Spatial Practice | استودیو طراحی و فضا
A5: LANDSCAPE DESIGN & TECHNICAL BOQ
A6: دفترچه طراحی منظر و برآورد فنی
A7: حیاط پشتی ویلای مسکونی · قائم‌شهر، مازندران | Residential Backyard · Qaemshahr, Mazandaran | ≈ 495 m²
A10: شناسنامه سند / DOCUMENT CONTROL
A11: پروژه / Project | C11: حیاط پشتی ویلای مسکونی — Residential Backyard Villa | E11: کارفرما / Client | G11: —
A12: مکان / Location | C12: قائمشهر، مازندران / Qaemshahr, Mazandaran | E12: مساحت سایت / Site Area | G12: ≈ 495 m²
A13: شماره سند / Doc No. | C13: ME-LS-00 · Rev 02 | E13: تاریخ / Date | G13: 1405/07 · Oct 2026
A14: وضعیت / Status | C14: جهت استعلام / Issued for Pricing | E14: واحد پول / Currency | G14: تومان / Toman
A15: تهیه و طراحی / Prepared & Designed by | C15: MAJID EISAPOUR | E15: سطح خدمات / Deliverable | G15: Concept + BOQ + Technical Notes
A16: فهرست مطالب / CONTENTS
A17: 00 | B17: جلد و هویت / Cover & Identity
A18: 01 | B18: شناسنامه پروژه / Project Information
A19: 02 | B19: روایت و ایده طراحی / Design Narrative
A20: 03 | B20: مبنای طراحی و دامنه کار / Design Basis & Scope
A21: 04 | B21: جدول مقادیر و برآورد / Bill of Quantities
A22: 05 | B22: جدول متریال / Material Schedule
A23: 06 | B23: پالت کاشت / Planting Schedule
A24: 07 | B24: نورپردازی و آبیاری / Lighting & Irrigation
A25: 08 | B25: یادداشت‌های اجرایی / Technical Notes & QA
A26: 09 | B26: خلاصه هزینه / Cost Summary & Control
A27: 10 | B27: تاریخچه نسخه‌ها / Revision Log
A29: بیانیه طراحی / DESIGN STATEMENT
A30: «فضا فقط ساخته نمی‌شود؛ طراحی می‌شود، تجربه می‌شود و به بخشی از زندگی تبدیل می‌شود.» “Space is not merely built; it is designed, experienced, and made part of everyday life.”
A32: MAJID EISAPOUR · DESIGN & SPATIAL PRACTICE | DOC ME-LS-00 · REV 02 · 1405 | CONFIDENTIAL — PREPARED FOR CLIENT REVIEW

Sheet 01 | Project Info
A1: PROJECT INFORMATION | F1: ME-LS-01
A2: مشخصات پروژه | F2: REV 02 · 1405/07 · Oct 2026
A3: A concise bilingual project identity sheet | شناسنامه پروژه
A5: عنوان / Title | B5: مقدار / Value | C5: عنوان / Title | D5: مقدار / Value | E5: عنوان / Title | F5: مقدار / Value | G5: عنوان / Title | H5: مقدار / Value
A6: کارفرما / Client | B6: — | C6: مکان / Location | D6: قائم‌شهر، مازندران / Qaemshahr, Mazandaran | E6: مساحت سایت / Site Area | F6: ≈ 495 m² | G6: تاریخ / Date | H6: 1405 / 2026
A7: نوع پروژه / Project Type | B7: طراحی منظر حیاط ویلایی / Residential Backyard Landscape | C7: زبان طراحی / Design Language | D7: Contemporary • Natural • Architectural | E7: مقیاس مبنا / Working Scale | F7: 1:100 Concept | G7: نسخه / Revision | H7: 02
A8: رویکرد / Approach | B8: Outdoor Room / اتاقِ بیرونی | C8: برنامه / Program | D8: Kitchen Garden + Social Space + Pavilion | E8: سطح خدمات / Deliverable | F8: Concept + BOQ + Technical Notes | G8: تهیه‌کننده / Prepared by | H8: MAJID EISAPOUR
A9: واحد پول / Currency | B9: تومان / Toman | C9: وضعیت مدرک / Document Status | D9: جهت استعلام / Issued for Pricing | E9: شماره سند / Doc No. | F9: ME-LS-01 · Rev 02 | G9: مبنای قیمت / Pricing Basis | H9: برآورد تفصیلی — بدون مالیات بر ارزش افزوده
A11: هویت طراحی / Design Identity
A12: Design Identity / هویت طراحی A calm, contemporary garden organized as an outdoor room: productive planting to the north, a generous green heart at the center, and an architectural social space toward the south-west. The service edge remains intact and is treated as an existing condition rather than a redesign scope. باغی معاصر و آرام که همچون یک اتاقِ بیرونی سازمان‌دهی شده است: باغ سبزیِ کاربردی در شمال، قلب سبز و باز در مرکز، و فضای اجتماعیِ معماری‌شده در جنوب‌غرب. لبه خدماتی موجود دست‌نخورده باقی می‌ماند و صرفاً به‌عنوان یک وضعیت موجود در نظر گرفته شده است.
A13: تمام مقادیر و مبالغ این دفترچه از مبانی برگه ۰۳ استخراج شده‌اند؛ برای جزئیات به برگه‌های ۰۴ تا ۰۹ مراجعه شود.

Sheet 02 | Design Narrative
A1: DESIGN NARRATIVE | C1: ME-LS-02
A2: روایت و ایده طراحی | C2: REV 02
A3: Concept, atmosphere and spatial sequence | روایت، اتمسفر و توالی فضایی
A5: ID | B5: موضوع / Topic | C5: عنوان / Title | D5: متن حرفه‌ای / Professional Narrative
A6: 01 | B6: ایده مرکزی / Core Idea | C6: OUTDOOR ROOM — اتاقِ بیرونی | D6: The garden is conceived as an extension of domestic life, not as a collection of isolated objects. باغ به‌عنوان امتداد زندگی روزمره طراحی شده است، نه مجموعه‌ای از عناصر جدا از هم.
A7: 02 | B7: توالی ورود / Arrival Sequence | C7: FROM PARKING TO GARDEN — از مسیر به باغ | D7: The entrance begins directly from the parking corridor; the path becomes a spatial threshold through texture, planting and controlled views. ورودی مستقیماً از مسیر پارکینگ آغاز می‌شود و با تغییر بافت، کاشت و کنترل دید به یک آستانه فضایی تبدیل می‌شود.
A8: 03 | B8: قلب سبز / Green Heart | C8: OPEN LAWN — میدان سبز | D8: A quiet central clearing balances the hardscape and gives the garden visual breathing room. فضای سبز مرکزی، تعادل میان کف‌سازی و کاشت را برقرار کرده و به باغ فرصت تنفس بصری می‌دهد.
A9: 04 | B9: فضای زندگی / Living Space | C9: PAVILION + TERRACE — پاویون و تراس | D9: A compact architectural pavilion and open terrace form one continuous social composition. پاویون و تراس باز به‌عنوان یک ترکیب پیوسته برای نشستن، گفت‌وگو و مکث شکل می‌گیرند.
A10: 05 | B10: آب معماری / Architectural Water | C10: LINEAR WATER — آبنمای خطی | D10: A narrow linear water element accompanies circulation as a reflective architectural line rather than a standalone fountain. آب به‌صورت یک خط باریک و بازتابنده در کنار مسیر حرکت قرار می‌گیرد، نه به‌عنوان آبنمایی مستقل و جداافتاده.
A12: توالی فضایی: ورودی از پارکینگ ← آستانه کاشت ← قلب سبز ← پاویون و تراس ← آبنمای خطی

Sheet 03 | Design Basis
A1: DESIGN BASIS & SCOPE | F1: ME-LS-03
A2: مبنای طراحی و دامنه کار | F2: REV 02
A3: What is included, what remains existing, and the assumptions behind the BOQ | مبنای محاسبات
A5: کد / Code | B5: موضوع / Topic | C5: مبنای طراحی / Basis | D5: وضعیت / Status | E5: واحد / Unit | F5: مقدار / Qty | G5: یادداشت / Note | H5: توضیح / Description
A6: B-01 | B6: مساحت سایت / Site Area | C6: 20.2 × 24.5 = 494.9 | D6: مبنای محاسبه / Basis | E6: m² | F6: 495 | G6: Conceptual | H6: فقط حیاط پشتی / Backyard only
A7: B-02 | B7: پاویون / Pavilion | C7: 5.40 × 4.80 | D7: طراحی / Design | E7: m² | F7: 25.9 | G7: Indicative | H7: طرح سازه نهایی توسط مهندس سازه
A8: B-03 | B8: تراس باز / Open Terrace | C8: 6.60 × 3.20 ≈ 21.1 | D8: طراحی / Design | E8: m² | F8: 21.1 | G8: Indicative | H8: یکپارچه با پاویون / Integrated with pavilion
A9: B-04 | B9: آبنمای خطی / Linear Water | C9: 11.00 × 0.50 | D9: طراحی / Design | E9: m² | F9: 5.5 | G9: Indicative | H9: عنصر بازتابنده و معماری / Reflective element
A10: B-05 | B10: باغ سبزی / Kitchen Garden | C10: زون 120 m² = 90 بستر + 30 دسترسی | D10: طراحی / Design | E10: m² | F10: 120 | G10: Seasonal | H10: بستر خالص کاشت 90 m² (تطبیق با BOQ 09-01 و P-05)
A11: B-06 | B11: لبه خدماتی / Service Edge | C11: Storage + washing + lobby | D11: موجود / Existing | E11: — | F11: — | G11: Untouched | H11: بدون طراحی مجدد / No redesign included
A12: B-07 | B12: ورودی / Entry | C12: Direct from parking corridor | D12: موجود / Existing | E12: — | F12: — | G12: Integrated | H12: بدون درب/گیت فرض شده / No gate assumed
A13: B-08 | B13: کفپوش سخت / Hardscape Paving | C13: مسیر 45 + تراس 22 = 67 | D13: طراحی / Design | E13: m² | F13: 67 | G13: Indicative | H13: تطبیق با BOQ 03-01 و 05-01 و M-01
A14: B-09 | B14: چمن / Lawn | C14: قلب سبز مرکزی / Central green heart | D14: طراحی / Design | E14: m² | F14: 140 | G14: Indicative | H14: تطبیق با BOQ 08-01 و P-06
A15: B-10 | B15: تفکیک سطوح / Area Breakdown | C15: 67 سخت + 140 چمن + 120 باغ سبزی + ≈168 کاشت و لبه | D15: کنترلی / Control | E15: m² | F15: 495 | G15: Indicative | H15: جمع کنترلی با B-01 / Reconciles with B-01
A17: جمع‌بندی / Reconciliation: مقادیر جدول BOQ (برگه ۰۴) مستقیماً از همین مبانی استخراج شده‌اند؛ هر تغییر در مبانی، بازنگری مقادیر و مبالغ را الزامی می‌کند. اقلام بدون مقدار (—) در دامنه این دفترچه نیستند.

Sheet 04 | BOQ | برآورد
A1: BILL OF QUANTITIES — BOQ | F1: ME-LS-04
A2: جدول مقادیر و برآورد هزینه | F2: REV 02
A3: Formula-driven technical estimate · تمام مبالغ به تومان و بدون مالیات بر ارزش افزوده | برآورد فرمول‌محور
A5: کد / Code | B5: بخش و آیتم / Item | C5: شرح فنی و ریزجزئیات / Technical Description | D5: واحد / Unit | E5: مقدار / Qty | F5: قیمت واحد / Unit Rate (Toman) | G5: مبلغ کل / Total (Toman) | H5: مبنای محاسبه، ارجاعات و نکات اجرا / Basis & Notes
A6: 01 | B6: تجهیز کارگاه و حفاظت / SITE SETUP & PROTECTION
A7: 01-01 | B7: تجهیز کارگاه / Site Setup | C7: محافظت از محدوده موجود، ابزار و تجهیز اولیه | D7: مقطوع (LS) | E7: 1 | F7: 35000000 | G7: =E7*F7 | H7: شروع پروژه؛ ورود به لبه خدماتی ممنوع (→ B-06)
A8: 02 | B8: عملیات خاکی و آماده‌سازی بستر / EARTHWORK & SOIL PREPARATION
A9: 02-01 | B9: خاک‌برداری / Excavation | C9: برداشت موضعی برای زیرسازی مسیرها و سازه | D9: m³ | E9: 35 | F9: 450000 | G9: =E9*F9 | H9: برداشت موضعی و کنترل‌شده (→ B-02، B-03)
A10: 02-02 | B10: خاک زراعی / Topsoil | C10: تأمین، اصلاح و پخش خاک زراعی | D10: m³ | E10: 28 | F10: 700000 | G10: =E10*F10 | H10: بستر کاشت و باغ سبزی (→ M-06)
A11: 02-03 | B11: کمپوست / Compost | C11: ماده آلی و اصلاح خاک | D11: m³ | E11: 8 | F11: 950000 | G11: =E11*F11 | H11: اختلاط کنترل‌شده (→ M-06، TN-07)
B12: جمع بخش 02 / Section 02 Subtotal | G12: =SUM(G9:G11) | H12: =IF(ABS(G12-SUM(G9,G10,G11))<1,"OK","CHECK")
A13: 03 | B13: کف‌پوش و محوطه سخت / PAVING & HARDSCAPE
A14: 03-01 | B14: کف‌سازی سنگ / Stone Paving | C14: سنگ طبیعی، برش، ملات/بستر و بندکشی | D14: m² | E14: 45 | F14: 3200000 | G14: =E14*F14 | H14: مسیرها؛ سنگ منتخب (→ M-01)
A15: 03-02 | B15: زیرسازی / Subbase | C15: مصالح دانه‌بندی‌شده + تراکم مرحله‌ای | D15: m³ | E15: 28 | F15: 900000 | G15: =E15*F15 | H15: تراکم مرحله‌ای الزامی است (→ TN-01)
B16: جمع بخش 03 / Section 03 Subtotal | G16: =SUM(G14:G15) | H16: =IF(ABS(G16-SUM(G14,G15))<1,"OK","CHECK")
A17: 04 | B17: پاویون / PAVILION
A18: 04-01 | B18: فونداسیون پاویون / Foundation | C18: بتن، آرماتور و قالب‌بندی اولیه | D18: m² | E18: 30 | F18: 8500000 | G18: =E18*F18 | H18: ضخامت مبنا ≈20 سانتی‌متر ≈ 6 m³ بتن (→ M-04، TN-03)
A19: 04-02 | B19: اسکلت فلزی / Steel Frame | C19: پروفیل، برش، جوش، ضدزنگ و نصب | D19: kg | E19: 1200 | F19: 210000 | G19: =E19*F19 | H19: وزن تقریبی؛ تأیید مهندس سازه (→ M-03)
A20: 04-03 | B20: سقف / Roof | C20: پوسته سقف و لایه‌های آب‌بندی | D20: m² | E20: 32 | F20: 4200000 | G20: =E20*F20 | H20: هماهنگ با دیتیل معماری (→ B-02)
A21: 04-04 | B21: ترمووود / Thermowood | C21: سقف کاذب و پوسته چوبی منتخب | D21: m² | E21: 30 | F21: 3500000 | G21: =E21*F21 | H21: وابسته به گونه و گرید (→ M-02، TN-04)
B22: جمع بخش 04 / Section 04 Subtotal | G22: =SUM(G18:G21) | H22: =IF(ABS(G22-SUM(G18,G19,G20,G21))<1,"OK","CHECK")
A23: 05 | B23: تراس باز / OPEN TERRACE
A24: 05-01 | B24: تراس / Terrace | C24: کف‌سازی و لبه‌سازی فضای نشستن | D24: m² | E24: 22 | F24: 3000000 | G24: =E24*F24 | H24: یکپارچه با پاویون (→ B-03، M-01)
A25: 06 | B25: آبنمای خطی / LINEAR WATER FEATURE
A26: 06-01 | B26: آبنمای خطی / Linear Water | C26: کاسه، آب‌بندی، لبه سنگی و گردش بسته آب | D26: lm | E26: 11 | F26: 15000000 | G26: =E26*F26 | H26: آبنمای کم‌عمق و معماری (→ B-04، M-05، TN-06)
A27: 07 | B27: آبیاری / IRRIGATION
A28: 07-01 | B28: آبیاری / Irrigation Network | C28: شبکه اصلی، تفکیک زون و کنترل | D28: m² | E28: 495 | F28: 190000 | G28: =E28*F28 | H28: شامل شبکه اصلی ≈120 lm و 6 عدد شیر برقی (→ I-01، I-03، TN-08)
A29: 07-02 | B29: لوله قطره‌ای / Drip Line | C29: لوله و اتصالات قطره‌ای | D29: lm | E29: 350 | F29: 100000 | G29: =E29*F29 | H29: ویژه باغ سبزی و کاشت (→ I-02)
B30: جمع بخش 07 / Section 07 Subtotal | G30: =SUM(G28:G29) | H30: =IF(ABS(G30-SUM(G28,G29))<1,"OK","CHECK")
A31: 08 | B31: کاشت و چمن / PLANTING & LAWN
A32: 08-01 | B32: چمن / Lawn | C32: زیرسازی و اجرای چمن | D32: m² | E32: 140 | F32: 270000 | G32: =E32*F32 | H32: چمن مقاوم و کم‌دردسر (→ P-06)
A33: 08-02 | B33: درخت شاخص / Specimen Tree | C33: درخت شاخص با کاشت و تثبیت | D33: عدد | E33: 2 | F33: 12000000 | G33: =E33*F33 | H33: انتخاب نهایی با توجه به اقلیم (→ P-01)
A34: 08-03 | B34: درخت میوه / Fruit Tree | C34: نهال میوه مناسب منطقه | D34: عدد | E34: 4 | F34: 5500000 | G34: =E34*F34 | H34: در محدوده باغ تولیدی (→ P-02)
A35: 08-04 | B35: درختچه و پرچین / Shrub & Hedge | C35: کاشت درختچه چندلایه و پرچین | D35: عدد | E35: 35 | F35: 950000 | G35: =E35*F35 | H35: شامل پرچین 25 متر طول (→ P-03، P-04)
B36: جمع بخش 08 / Section 08 Subtotal | G36: =SUM(G32:G35) | H36: =IF(ABS(G36-SUM(G32,G33,G34,G35))<1,"OK","CHECK")
A37: 09 | B37: باغ سبزی / KITCHEN GARDEN
A38: 09-01 | B38: باغچه تولیدی / Raised Beds | C38: ساخت بسترهای کاشت سبزی | D38: m² | E38: 90 | F38: 1500000 | G38: =E38*F38 | H38: بستر خالص در زون 120 m² (→ B-05، P-05)
A39: 10 | B39: روشنایی محوطه / LIGHTING
A40: 10-01 | B40: چراغ مسیر / Path Light | C40: چراغ محوطه با IP مناسب | D40: عدد | E40: 10 | F40: 4800000 | G40: =E40*F40 | H40: نور کم‌ارتفاع و کنترل‌شده (→ L-01، TN-05)
A41: 10-02 | B41: چراغ توکار / Inground Light | C41: نورپردازی تأکیدی معماری | D41: عدد | E41: 8 | F41: 5200000 | G41: =E41*F41 | H41: بدون خیرگی؛ درین مناسب (→ L-02)
...

Sheet 05 | Material Schedule
A1: MATERIAL SCHEDULE | E1: ME-LS-05
A2: جدول متریال و مشخصات | E2: REV 02
A3: Material language, application and execution intent | زبان متریال، کاربرد و قصد اجرایی
A5: کد / Code | B5: متریال / Material | C5: کاربرد / Application | D5: حس و کیفیت / Character | E5: واحد / Unit | F5: مقدار / Qty | G5: یادداشت اجرایی / Execution Note
A6: M-01 | B6: سنگ طبیعی / Natural Stone | C6: مسیرها و تراس | D6: Calm • tactile • durable | E6: m² | F6: ≈ 67 | G6: جمع 45 مسیر + 22 تراس؛ نمونه و گرید نهایی پیش از سفارش تأیید شود (→ BOQ 03-01، 05-01)
A7: M-02 | B7: ترمووود / Thermowood | C7: سقف و جزئیات پاویون | D7: Warm • precise • natural | E7: m² | F7: ≈ 30 | G7: زیرسازی و فاصله تهویه پشت چوب الزامی است (→ TN-04)
A8: M-03 | B8: فلز رنگ‌شده / Coated Steel | C8: اسکلت پاویون | D8: Light • minimal • architectural | E8: kg | F8: ≈ 1,200 | G8: ضدخوردگی مناسب رطوبت شمال (→ BOQ 04-02)
A9: M-04 | B9: بتن / Concrete | C9: فونداسیون و بسترها | D9: Mass • quiet • robust | E9: m³ | F9: ≈ 6 | G9: معادل پی 30 m² با ضخامت ≈20 cm؛ عیار توسط مهندس (→ BOQ 04-01)
A10: M-05 | B10: آب / Water | C10: آبنمای خطی | D10: Reflective • sensory • calm | E10: lm | F10: ≈ 11 | G10: گردش بسته و دسترسی سرویس (→ BOQ 06-01)
A11: M-06 | B11: خاک اصلاح‌شده و کمپوست / Amended Soil & Compost | C11: بستر کاشت و باغ سبزی | D11: Living • fertile • local | E11: m³ | F11: ≈ 36 | G11: جمع 28 خاک زراعی + 8 کمپوست (→ BOQ 02-02، 02-03)
A13: مقادیر این برگه با برگه ۰۴ (BOQ) و برگه ۰۳ (مبانی) هم‌خوان شده‌اند؛ جمع سنگ 45 + 22 = 67 m² و جمع خاک 28 + 8 = 36 m³.

Sheet 06 | Planting Schedule
A1: PLANTING SCHEDULE | E1: ME-LS-06
A2: پالت کاشت و برنامه سبز | E2: REV 02
A3: A layered, seasonal and maintainable planting strategy | پالت کاشت لایه‌ای، فصلی و قابل نگهداری
A5: کد / Code | B5: گروه / Group | C5: نقش / Role | D5: مکان / Zone | E5: واحد / Unit | F5: مقدار / Qty | G5: راهنمای انتخاب / Selection Guide
A6: P-01 | B6: درخت شاخص / Specimen | C6: Focal tree / نقطه کانونی | D6: مرکز باغ | E6: عدد | F6: 2 | G6: فرم معماری، سایه ملایم، سازگار با اقلیم (→ BOQ 08-02)
A7: P-02 | B7: درخت میوه / Fruit | C7: Productive layer / لایه تولیدی | D7: شمال | E7: عدد | F7: 4 | G7: گونه‌های سازگار با اقلیم و نگهداری واقعی (→ BOQ 08-03)
A8: P-03 | B8: درختچه / Shrub | C8: Structure + texture / ساختار و بافت | D8: حاشیه‌ها | E8: عدد | F8: 35 | G8: ترکیب همیشه‌سبز و فصلی (→ BOQ 08-04)
A9: P-04 | B9: پرچین / Hedge | C9: Filter + frame / فیلتر و قاب | D9: لبه‌ها | E9: lm | F9: 25 | G9: ارتفاع نهایی کنترل‌شده؛ در ردیف 08-04 لحاظ شده است
A10: P-05 | B10: سبزی فصلی / Seasonal Vegetable | C10: Edible landscape / منظر خوراکی | D10: باغ سبزی شمال | E10: m² | F10: 90 | G10: بستر خالص از زون 120 m² باغ سبزی (→ B-05، BOQ 09-01)
A11: P-06 | B11: چمن / Lawn | C11: Visual breathing room / تنفس بصری | D11: مرکز | E11: m² | F11: 140 | G11: سطح یکدست و مقاوم (→ BOQ 08-01)
A13: باغ سبزی: زون 120 m² شامل 90 m² بستر کاشت و 30 m² مسیر و دسترسی · پرچین 25 متر طول در ردیف 08-04 برآورد شده است.

Sheet 07 | Lighting & Irrigation
A1: LIGHTING & IRRIGATION | E1: ME-LS-07
A2: نورپردازی و آبیاری | E2: REV 02
A3: Invisible infrastructure, visible atmosphere | زیرساخت نامرئی، اتمسفرِ محسوس
A5: کد / Code | B5: سیستم / System | C5: عنصر / Element | D5: واحد / Unit | E5: مقدار / Qty | F5: اصل طراحی / Design Principle | G5: نکته فنی / Technical Note
A6: L-01 | B6: Lighting | C6: چراغ مسیر / Path Light | D6: عدد | E6: 10 | F6: Low glow / نور کم‌ارتفاع | G6: IP مناسب فضای باز؛ خیرگی کنترل شود (→ BOQ 10-01)
A7: L-02 | B7: Lighting | C7: چراغ توکار / Inground | D7: عدد | E7: 8 | F7: Accentuate architecture / تأکید معماری | G7: دسترسی سرویس و درین مناسب (→ BOQ 10-02)
A8: L-03 | B8: Lighting | C8: نور خطی آب / Water Light | D8: lm | E8: 10 | F8: Continuous reflection / بازتاب پیوسته | G8: کاملاً مناسب محیط مرطوب (→ BOQ 10-03)
A9: I-01 | B9: Irrigation | C9: شبکه اصلی / Main Line | D9: lm | E9: 120 | F9: Efficient distribution / توزیع کارا | G9: تفکیک زون‌های آبیاری (→ BOQ 07-01)
A10: I-02 | B10: Irrigation | C10: خط قطره‌ای / Drip Line | D10: lm | E10: 350 | F10: Water efficiency / بازده آبی | G10: ویژه باغ سبزی و کاشت (→ BOQ 07-02)
A11: I-03 | B11: Irrigation | C11: شیر برقی / Solenoid Valve | D11: عدد | E11: 6 | F11: Zone control / کنترل زون | G11: دسترسی برای تعمیرات (→ BOQ 07-01)
A13: شبکه اصلی آبیاری (120 lm) و شیرهای برقی (6 عدد) در ردیف 07-01 برآورد لحاظ شده‌اند؛ خط قطره‌ای 350 lm در ردیف 07-02.

Sheet 08 | Technical Notes
A1: TECHNICAL NOTES & QA | D1: ME-LS-08
A2: یادداشت‌های اجرایی و کنترل کیفیت | D2: REV 02
A3: Clear instructions for tender, execution and handover | دستور کار روشن برای استعلام، اجرا و تحویل
A5: کد / Code | B5: موضوع / Topic | C5: دستورالعمل / Instruction
A6: TN-01 | B6: زیرسازی / Subbase | C6: تمام سطوح سخت پیش از اجرای لایه نهایی باید متراکم، تراز و دارای شیب کنترل‌شده باشند (→ BOQ 03-02).
A7: TN-02 | B7: زهکشی / Drainage | C7: در اقلیم مرطوب، مسیر آب سطحی باید پیش از کف‌سازی حل شود؛ آب نباید به سازه پاویون هدایت شود.
A8: TN-03 | B8: پاویون / Pavilion | C8: ابعاد این دفتر مفهومی است؛ نقشه سازه، فونداسیون، اتصالات و جزئیات نهایی توسط مهندس ذی‌صلاح تأیید شود (→ BOQ 04).
A9: TN-04 | B9: چوب / Timber | C9: ترمووود باید از تأمین‌کننده معتبر و با گرید مناسب فضای بیرونی تهیه شود؛ زیرسازی و تهویه پشت چوب الزامی است (→ M-02).
A10: TN-05 | B10: نور / Lighting | C10: چراغ‌های فضای باز باید برای محیط مرطوب و بارندگی انتخاب شوند؛ مسیر کابل و دسترسی تعمیرات از ابتدا پیش‌بینی شود (→ BOQ 10).
A11: TN-06 | B11: آب / Water | C11: آبنمای خطی باید دارای گردش بسته، دسترسی سرویس، آب‌بندی مناسب و امکان تخلیه باشد (→ BOQ 06-01).
A12: TN-07 | B12: کاشت / Planting | C12: گونه‌ها بر اساس رطوبت، زهکشی، نور، نگهداری و دسترسی محلی نهایی شوند؛ این فهرست جایگزین انتخاب گیاه توسط مجری نیست.
A13: TN-08 | B13: لبه خدماتی / Existing Service Edge | C13: انبار، فضای شست‌وشوی نیمه‌باز و لابی موجود در دامنه طراحی مجدد نیستند و باید در زمان اجرا حفظ شوند (→ B-06).
A14: TN-09 | B14: مبنای برآورد / Estimating Basis | C14: تمام مقادیر از مبانی برگه 03 استخراج شده‌اند؛ پیش از اجرا برداشت نهایی (Take-off) و استعلام قیمت انجام شود. ردیف‌های مربوط به پرچین و شیر برقی در آیتم‌های 08-04 و 07-01 لحاظ شده‌اند. قیمت‌ها بدون احتساب مالیات بر ارزش افزوده است (→ BOQ).
A16: این یادداشت‌ها مکمل برگه ۰۴ هستند و در زمان استعلام قیمت و اجرا باید به پیمانکار ابلاغ شوند.

Sheet 09 | Cost Summary
A1: COST SUMMARY & CONTROL | F1: ME-LS-09
A2: خلاصه هزینه و کنترل برآورد | F2: REV 02
A3: A decision-ready financial snapshot · مبالغ به تومان | نمای مالی خوانا و تصمیم‌پذیر
A5: بخش / Section | B5: جمع / Total (Toman) | C5: سهم / Share | D5: کنترل / Check
A6: 01–02 | آماده‌سازی و زیرسازی / Preparation & Subbase | B6: =SUM('04 | BOQ | برآورد'!G7:G11) | C6: =B6/$B$15 | D6: =IF(ABS(B6-SUM('04 | BOQ | برآورد'!G7:G11))<1,"OK","CHECK")
A7: 03 | کف‌پوش و محوطه سخت / Paving & Hardscape | B7: =SUM('04 | BOQ | برآورد'!G14:G15) | C7: =B7/$B$15 | D7: =IF(ABS(B7-SUM('04 | BOQ | برآورد'!G14:G15))<1,"OK","CHECK")
A8: 04 | پاویون / Pavilion | B8: =SUM('04 | BOQ | برآورد'!G18:G21) | C8: =B8/$B$15 | D8: =IF(ABS(B8-SUM('04 | BOQ | برآورد'!G18:G21))<1,"OK","CHECK")
A9: 05–06 | تراس و آبنما / Terrace & Water | B9: =SUM('04 | BOQ | برآورد'!G24:G26) | C9: =B9/$B$15 | D9: =IF(ABS(B9-SUM('04 | BOQ | برآورد'!G24:G26))<1,"OK","CHECK")
A10: 07 | آبیاری / Irrigation | B10: =SUM('04 | BOQ | برآورد'!G28:G29) | C10: =B10/$B$15 | D10: =IF(ABS(B10-SUM('04 | BOQ | برآورد'!G28:G29))<1,"OK","CHECK")
A11: 08 | کاشت و چمن / Planting & Lawn | B11: =SUM('04 | BOQ | برآورد'!G32:G35) | C11: =B11/$B$15 | D11: =IF(ABS(B11-SUM('04 | BOQ | برآورد'!G32:G35))<1,"OK","CHECK")
A12: 09 | باغ سبزی / Kitchen Garden | B12: ='04 | BOQ | برآورد'!G38 | C12: =B12/$B$15 | D12: =IF(ABS(B12-'04 | BOQ | برآورد'!G38)<1,"OK","CHECK")
A13: 10 | روشنایی / Lighting | B13: =SUM('04 | BOQ | برآورد'!G40:G42) | C13: =B13/$B$15 | D13: =IF(ABS(B13-SUM('04 | BOQ | برآورد'!G40:G42))<1,"OK","CHECK")
A14: 11 | کنترل کیفیت و تحویل / QA & Handover | B14: ='04 | BOQ | برآورد'!G45 | C14: =B14/$B$15 | D14: =IF(ABS(B14-'04 | BOQ | برآورد'!G45)<1,"OK","CHECK")
A15: جمع مستقیم / Direct Cost | B15: =SUM(B6:B14)
A16: ذخیره ریسک و پرت / Risk & Waste Reserve | B16: =B15*C16 | C16: 0.1 | D16: ورودی / editable
A17: مالیات بر ارزش افزوده / VAT (در صورت اعمال) | B17: =B15*C17 | C17: 0 | D17: پیش‌فرض 0%
A18: برآورد کل / Estimated Total | B18: =B15+B16+B17 | C18: =B18/B15 | D18: کنترل / Control
A20: شاخص‌های کلیدی / KEY INDICATORS
A21: هزینه بر مترمربع سایت / Cost per site m² | B21: =B18/495
A22: سهم محوطه سخت، تراس و آب / Paving, terrace & water | B22: =(B7+B9)/B18
A23: سهم کاشت، چمن و باغ سبزی / Planting, lawn & kitchen garden | B23: =(B11+B12)/B18
A24: سهم پاویون / Pavilion share | B24: =B8/B18
A26: کنترل برآورد: برگه ۰۴ مبنا است و این برگه فقط جمع‌بندی می‌کند. ستون «کنترل» مغایرت جمع گروه با ردیف‌های BOQ را هشدار می‌دهد و ستون «سهم» بر پایه برآورد کل محاسبه می‌شود.

Sheet 10 | Revision Log
A1: REVISION LOG & DOCUMENT CONTROL | D1: ME-LS-10
A2: تاریخچه نسخه‌ها و کنترل مدارک | D2: REV 02
A3: Keep every issue traceable | کنترل نسخه و گردش مستندات
A5: نسخه / Rev. | B5: تاریخ / Date | C5: شرح تغییر / Description | D5: تهیه / Prepared | E5: بررسی / Checked | F5: تأیید / Approved
A6: 01 | B6: 1405 / 2026 | C6: نسخه پایه BOQ و ساختار حرفه‌ای دو زبانه | D6: MAJID EISAPOUR | E6: — | F6: —
A7: 02 | B7: 1405/07 · Oct 2026 | C7: بازطراحی گرافیکی و صفحه‌آرایی، اصلاح انسجام مقادیر بین برگه‌ها، افزودن ردیف‌های جمع بخش، شماره‌گذاری بخش‌ها (12 ← 11)، بازنویسی فرمول‌ها، اصلاح محدوده چاپ و تنظیمات پرینت | D7: MAJID EISAPOUR | E7: — | F7: —
A8: 03 | B8: — | C8: — | D8: — | E8: — | F8: —
A10: این دفترچه به‌صورت اسکریپت‌محور بازتولید می‌شود (tools/build_workbook.py)؛ هر اصلاح بعدی با نسخه جدید ثبت و قابل ردیابی است.
